Workbook

Sheet Cómo usarla
B2: Calculadora de precios para centros de estética
B3: Godolphy · Versión 2027
B5: Para qué sirve
B6: Calcula cuánto te cuesta de verdad cada servicio (producto, tu tiempo y la parte del alquiler y gastos fijos que le toca) y qué precio deberías cobrar para ganar el margen que quieres. Si ya tienes precio, te dice cuánto ganas realmente.
B8: Cómo rellenarla (10 minutos)
B9: 1. Pestaña «1. Costes fijos»: pon tus gastos de cada mes, los días y horas que abres, cuántas cabinas o puestos trabajan a la vez y cuánto quieres cobrar (o pagas) por hora de profesional.
B10: 2. Pestaña «2. Productos»: apunta los productos que gastas en los servicios, con el tamaño del envase y lo que te cuesta.
B11: 3. Pestaña «3. Servicios»: crea cada servicio con su duración, los productos que usa y el margen que quieres. Si ya tienes un precio, ponlo en «Tu precio actual» y verás tu margen real.
B13: Leyenda
B14: Celdas lila con texto azul = las rellenas tú. Celdas blancas con texto negro = se calculan solas, no las toques.
B15: Los datos que vienen puestos son un ejemplo para que veas cómo funciona. Sustitúyelos por los tuyos.
B17: Tres cosas importantes
... B23: Godolphy calcula tus números a partir de tus citas y cobros, sin hojas de cálculo: www.godolphy.com

Sheet 1. Costes fijos
B2: 1. Tus costes fijos de cada mes
B3: Lo que pagas cada mes tengas clientas o no. Ejemplo: sustitúyelo por tus cifras.
B5: Gasto mensual | C5: Importe (€/mes) | D5: Notas
B6: Alquiler del local | C6: 900
B7: Luz, agua e internet | C7: 250
B8: Cuota de autónoma / Seguridad Social | C8: 80 | D8: Tarifa plana el primer año; después según rendimientos
B9: Seguro de responsabilidad civil | C9: 25 | D9: Si lo pagas al año, divídelo entre 12
B10: Gestoría | C10: 90
B11: Software (agenda, reservas, facturación) | C11: 50
B12: Marketing y publicidad | C12: 150
B13: Amortización de aparatos y mobiliario | C13: 100 | D13: Ej.: 6.000 € de equipo a 5 años = 100 €/mes
B14: Otros | C14: 50
B18: Total costes fijos al mes | C18: =SUM(C6:C17) -> 1695
B20: Tu horario y tu capacidad
B21: Dato | C21: Valor | D21: Notas
B22: Días que abres al mes | C22: 22
B23: Horas que abres cada día | C23: 9
B24: Cabinas o puestos trabajando a la vez | C24: 2 | D24: Cuántas clientas puedes atender al mismo tiempo
B25: Ocupación realista | C25: 0.65 | D25: % de horas con clienta. Empieza con 50-70% si no lo sabes
B26: Coste por hora de profesional | C26: 15 | D26: Si tienes equipo: sueldo + Seguridad Social ÷ horas trabajadas. Si eres tú: lo que quieres ganar por hora
B27: Horas de servicio al mes | C27: =C22*C23*C24*C25 -> 257.4 | D27: Horas en las que de verdad facturas
B28: Coste fijo por hora de servicio | C28: =IF(C27>0,C18/C27,0) -> 6.5850816 | D28: Lo que le toca pagar a cada hora de servicio del alquiler y los gastos fijos

Sheet 2. Productos
B2: 2. Productos que usas en los servicios
B3: Un producto por fila. «Unidad» es cómo lo mides al usarlo: ml, g o unidades. Ejemplo: sustitúyelo por tus productos.
B5: Producto | C5: Unidad | D5: Cantidad del envase | E5: Precio del envase (€) | F5: Coste por unidad (€) | G5: Proveedor / notas
B6: Esmalte semipermanente | C6: ml | D6: 15 | E6: 12 | F6: =IF(AND(ISNUMBER(D6),D6>0,ISNUMBER(E6)),E6/D6,"") -> 0.8 | G6: Ej.
B7: Base y top coat | C7: ml | D7: 15 | E7: 10 | F7: =IF(AND(ISNUMBER(D7),D7>0,ISNUMBER(E7)),E7/D7,"") -> 0.66666667
B8: Acetona / removedor | C8: ml | D8: 1000 | E8: 9 | F8: =IF(AND(ISNUMBER(D8),D8>0,ISNUMBER(E8)),E8/D8,"") -> 0.009
B9: Lima y pulidor (desechables) | C9: unidades | D9: 50 | E9: 15 | F9: =IF(AND(ISNUMBER(D9),D9>0,ISNUMBER(E9)),E9/D9,"") -> 0.3
B10: Cera tibia | C10: g | D10: 800 | E10: 14 | F10: =IF(AND(ISNUMBER(D10),D10>0,ISNUMBER(E10)),E10/D10,"") -> 0.0175
B11: Bandas de depilación | C11: unidades | D11: 100 | E11: 6 | F11: =IF(AND(ISNUMBER(D11),D11>0,ISNUMBER(E11)),E11/D11,"") -> 0.06
B12: Crema facial profesional | C12: ml | D12: 500 | E12: 45 | F12: =IF(AND(ISNUMBER(D12),D12>0,ISNUMBER(E12)),E12/D12,"") -> 0.09
B13: Mascarilla facial | C13: unidades | D13: 10 | E13: 25 | F13: =IF(AND(ISNUMBER(D13),D13>0,ISNUMBER(E13)),E13/D13,"") -> 2.5
B14: Algodón y discos | C14: unidades | D14: 200 | E14: 5 | F14: =IF(AND(ISNUMBER(D14),D14>0,ISNUMBER(E14)),E14/D14,"") -> 0.025
F15: =IF(AND(ISNUMBER(D15),D15>0,ISNUMBER(E15)),E15/D15,"")
F16: =IF(AND(ISNUMBER(D16),D16>0,ISNUMBER(E16)),E16/D16,"")
F17: =IF(AND(ISNUMBER(D17),D17>0,ISNUMBER(E17)),E17/D17,"")
F18: =IF(AND(ISNUMBER(D18),D18>0,ISNUMBER(E18)),E18/D18,"")
F19: =IF(AND(ISNUMBER(D19),D19>0,ISNUMBER(E19)),E19/D19,"")
F20: =IF(AND(ISNUMBER(D20),D20>0,ISNUMBER(E20)),E20/D20,"")
F21: =IF(AND(ISNUMBER(D21),D21>0,ISNUMBER(E21)),E21/D21,"")
F22: =IF(AND(ISNUMBER(D22),D22>0,ISNUMBER(E22)),E22/D22,"")
F23: =IF(AND(ISNUMBER(D23),D23>0,ISNUMBER(E23)),E23/D23,"")
F24: =IF(AND(ISNUMBER(D24),D24>0,ISNUMBER(E24)),E24/D24,"")
F25: =IF(AND(ISNUMBER(D25),D25>0,ISNUMBER(E25)),E25/D25,"")
F26: =IF(AND(ISNUMBER(D26),D26>0,ISNUMBER(E26)),E26/D26,"")
... F155: =IF(AND(ISNUMBER(D155),D155>0,ISNUMBER(E155)),E155/D155,"")

Sheet 3. Servicios
B2: 3. Tus servicios: coste real y precio
B3: Las cantidades van en la unidad del producto (ml, g o unidades). Ejemplo: sustitúyelo por tus servicios.
B5: Servicio | C5: Duración (min) | D5: Producto 1 | E5: Cantidad 1 | F5: Producto 2 | G5: Cantidad 2 | H5: Producto 3 | I5: Cantidad 3 | J5: Otros costes por servicio (€) | K5: Margen que quieres | L5: IVA | M5: Coste de producto | N5: Coste de profesional | O5: Coste fijo (local y gastos) | P5: COSTE TOTAL | Q5: PRECIO RECOMENDADO sin IVA | R5: PRECIO RECOMENDADO con IVA | S5: Tu precio actual (con IVA) | T5: Beneficio por servicio | U5: Margen real | V5: Diagnóstico
B6: Manicura semipermanente | C6: 60 | D6: Esmalte semipermanente | E6: 0.5 | F6: Base y top coat | G6: 0.6 | H6: Lima y pulidor (desechables) | I6: 1 | J6: 0.5 | K6: 0.35 | L6: 0.21 | M6: =IF(B6="","",IF(OR(D6="",E6=""),0,IFERROR(INDEX('2. Productos'!$F$6:$F$155,MATCH(D6,'2. Productos'!$B$6:$B$155,0))*E6,0))+IF(OR(F6="",G6=""),0,IFERROR(INDEX('2. Productos'!$F$6:$F$155,MATCH(F6,'2. Productos'!$B$6:$B$155,0))*G6,0))+IF(OR(H6="",I6=""),0,IFERROR(INDEX('2. Productos'!$F$6:$F$155,MATCH(H6,'2. Productos'!$B$6:$B$155,0))*I6,0))) -> 1.1 | N6: =IF(B6="","",N(C6)/60*'1. Costes fijos'!C26) -> 15 | O6: =IF(B6="","",N(C6)/60*'1. Costes fijos'!C28) -> 6.5850816 | P6: =IF(B6="","",M6+N6+O6+N(J6)) -> 23.185082 | Q6: =IF(B6="","",IF(N(K6)>=1,"Margen < 100%",P6/(1-N(K6)))) -> 35.669356 | R6: =IF(OR(B6="",NOT(ISNUMBER(Q6))),"",Q6*(1+N(L6))) -> 43.159921 | S6: 20 | T6: =IF(OR(B6="",NOT(ISNUMBER(S6))),"",S6/(1+N(L6))-P6) -> -6.656156 | U6: =IF(OR(B6="",NOT(ISNUMBER(S6)),N(S6)=0),"",T6/(S6/(1+N(L6)))) -> -0.40269744 | V6: =IF(U6="","",IF(T6<0,"Pierdes dinero",IF(U6<N(K6),"Por debajo de tu margen","Bien"))) -> Pierdes dinero
B7: Retirada + manicura semipermanente | C7: 75 | D7: Esmalte semipermanente | E7: 0.5 | F7: Acetona / removedor | G7: 20 | H7: Lima y pulidor (desechables) | I7: 1 | J7: 0.5 | K7: 0.35 | L7: 0.21 | M7: =IF(B7="","",IF(OR(D7="",E7=""),0,IFERROR(INDEX('2. Productos'!$F$6:$F$155,MATCH(D7,'2. Productos'!$B$6:$B$155,0))*E7,0))+IF(OR(F7="",G7=""),0,IFERROR(INDEX('2. Productos'!$F$6:$F$155,MATCH(F7,'2. Productos'!$B$6:$B$155,0))*G7,0))+IF(OR(H7="",I7=""),0,IFERROR(INDEX('2. Productos'!$F$6:$F$155,MATCH(H7,'2. Productos'!$B$6:$B$155,0))*I7,0))) -> 0.88 | N7: =IF(B7="","",N(C7)/60*'1. Costes fijos'!C26) -> 18.75 | O7: =IF(B7="","",N(C7)/60*'1. Costes fijos'!C28) -> 8.231352 | P7: =IF(B7="","",M7+N7+O7+N(J7)) -> 28.361352 | Q7: =IF(B7="","",IF(N(K7)>=1,"Margen < 100%",P7/(1-N(K7)))) -> 43.632849 | R7: =IF(OR(B7="",NOT(ISNUMBER(Q7))),"",Q7*(1+N(L7))) -> 52.795748 | S7: 25 | T7: =IF(OR(B7="",NOT(ISNUMBER(S7))),"",S7/(1+N(L7))-P7) -> -7.700195 | U7: =IF(OR(B7="",NOT(ISNUMBER(S7)),N(S7)=0),"",T7/(S7/(1+N(L7)))) -> -0.37268944 | V7: =IF(U7="","",IF(T7<0,"Pierdes dinero",IF(U7<N(K7),"Por debajo de tu margen","Bien"))) -> Pierdes dinero
B8: Depilación piernas enteras (cera) | C8: 40 | D8: Cera tibia | E8: 60 | F8: Bandas de depilación | G8: 10 | J8: 0.3 | K8: 0.35 | L8: 0.21 | M8: =IF(B8="","",IF(OR(D8="",E8=""),0,IFERROR(INDEX('2. Productos'!$F$6:$F$155,MATCH(D8,'2. Productos'!$B$6:$B$155,0))*E8,0))+IF(OR(F8="",G8=""),0,IFERROR(INDEX('2. Productos'!$F$6:$F$155,MATCH(F8,'2. Productos'!$B$6:$B$155,0))*G8,0))+IF(OR(H8="",I8=""),0,IFERROR(INDEX('2. Productos'!$F$6:$F$155,MATCH(H8,'2. Productos'!$B$6:$B$155,0))*I8,0))) -> 1.65 | N8: =IF(B8="","",N(C8)/60*'1. Costes fijos'!C26) -> 10 | O8: =IF(B8="","",N(C8)/60*'1. Costes fijos'!C28) -> 4.3900544 | P8: =IF(B8="","",M8+N8+O8+N(J8)) -> 16.340054 | Q8: =IF(B8="","",IF(N(K8)>=1,"Margen < 100%",P8/(1-N(K8)))) -> 25.138545 | R8: =IF(OR(B8="",NOT(ISNUMBER(Q8))),"",Q8*(1+N(L8))) -> 30.41764 | S8: 25 | T8: =IF(OR(B8="",NOT(ISNUMBER(S8))),"",S8/(1+N(L8))-P8) -> 4.3211026 | U8: =IF(OR(B8="",NOT(ISNUMBER(S8)),N(S8)=0),"",T8/(S8/(1+N(L8)))) -> 0.20914137 | V8: =IF(U8="","",IF(T8<0,"Pierdes dinero",IF(U8<N(K8),"Por debajo de tu margen","Bien"))) -> Por debajo de tu margen
B9: Limpieza facial | C9: 60 | D9: Crema facial profesional | E9: 8 | F9: Mascarilla facial | G9: 1 | H9: Algodón y discos | I9: 6 | J9: 1 | K9: 0.35 | L9: 0.21 | M9: =IF(B9="","",IF(OR(D9="",E9=""),0,IFERROR(INDEX('2. Productos'!$F$6:$F$155,MATCH(D9,'2. Productos'!$B$6:$B$155,0))*E9,0))+IF(OR(F9="",G9=""),0,IFERROR(INDEX('2. Productos'!$F$6:$F$155,MATCH(F9,'2. Productos'!$B$6:$B$155,0))*G9,0))+IF(OR(H9="",I9=""),0,IFERROR(INDEX('2. Productos'!$F$6:$F$155,MATCH(H9,'2. Productos'!$B$6:$B$155,0))*I9,0))) -> 3.37 | N9: =IF(B9="","",N(C9)/60*'1. Costes fijos'!C26) -> 15 | O9: =IF(B9="","",N(C9)/60*'1. Costes fijos'!C28) -> 6.5850816 | P9: =IF(B9="","",M9+N9+O9+N(J9)) -> 25.955082 | Q9: =IF(B9="","",IF(N(K9)>=1,"Margen < 100%",P9/(1-N(K9)))) -> 39.930895 | R9: =IF(OR(B9="",NOT(ISNUMBER(Q9))),"",Q9*(1+N(L9))) -> 48.316383 | S9: 35 | T9: =IF(OR(B9="",NOT(ISNUMBER(S9))),"",S9/(1+N(L9))-P9) -> 2.9705382 | U9: =IF(OR(B9="",NOT(ISNUMBER(S9)),N(S9)=0),"",T9/(S9/(1+N(L9)))) -> 0.10269575 | V9: =IF(U9="","",IF(T9<0,"Pierdes dinero",IF(U9<N(K9),"Por debajo de tu margen","Bien"))) -> Por debajo de tu margen
M10: =IF(B10="","",IF(OR(D10="",E10=""),0,IFERROR(INDEX('2. Productos'!$F$6:$F$155,MATCH(D10,'2. Productos'!$B$6:$B$155,0))*E10,0))+IF(OR(F10="",G10=""),0,IFERROR(INDEX('2. Productos'!$F$6:$F$155,MATCH(F10,'2. Productos'!$B$6:$B$155,0))*G10,0))+IF(OR(H10="",I10=""),0,IFERROR(INDEX('2. Productos'!$F$6:$F$155,MATCH(H10,'2. Productos'!$B$6:$B$155,0))*I10,0))) | N10: =IF(B10="","",N(C10)/60*'1. Costes fijos'!C26) | O10: =IF(B10="","",N(C10)/60*'1. Costes fijos'!C28) | P10: =IF(B10="","",M10+N10+O10+N(J10)) | Q10: =IF(B10="","",IF(N(K10)>=1,"Margen < 100%",P10/(1-N(K10)))) | R10: =IF(OR(B10="",NOT(ISNUMBER(Q10))),"",Q10*(1+N(L10))) | T10: =IF(OR(B10="",NOT(ISNUMBER(S10))),"",S10/(1+N(L10))-P10) | U10: =IF(OR(B10="",NOT(ISNUMBER(S10)),N(S10)=0),"",T10/(S10/(1+N(L10)))) | V10: =IF(U10="","",IF(T10<0,"Pierdes dinero",IF(U10<N(K10),"Por debajo de tu margen","Bien")))
M11: =IF(B11="","",IF(OR(D11="",E11=""),0,IFERROR(INDEX('2. Productos'!$F$6:$F$155,MATCH(D11,'2. Productos'!$B$6:$B$155,0))*E11,0))+IF(OR(F11="",G11=""),0,IFERROR(INDEX('2. Productos'!$F$6:$F$155,MATCH(F11,'2. Productos'!$B$6:$B$155,0))*G11,0))+IF(OR(H11="",I11=""),0,IFERROR(INDEX('2. Productos'!$F$6:$F$155,MATCH(H11,'2. Productos'!$B$6:$B$155,0))*I11,0))) | N11: =IF(B11="","",N(C11)/60*'1. Costes fijos'!C26) | O11: =IF(B11="","",N(C11)/60*'1. Costes fijos'!C28) | P11: =IF(B11="","",M11+N11+O11+N(J11)) | Q11: =IF(B11="","",IF(N(K11)>=1,"Margen < 100%",P11/(1-N(K11)))) | R11: =IF(OR(B11="",NOT(ISNUMBER(Q11))),"",Q11*(1+N(L11))) | T11: =IF(OR(B11="",NOT(ISNUMBER(S11))),"",S11/(1+N(L11))-P11) | U11: =IF(OR(B11="",NOT(ISNUMBER(S11)),N(S11)=0),"",T11/(S11/(1+N(L11)))) | V11: =IF(U11="","",IF(T11<0,"Pierdes dinero",IF(U11<N(K11),"Por debajo de tu margen","Bien")))
M12: =IF(B12="","",IF(OR(D12="",E12=""),0,IFERROR(INDEX('2. Productos'!$F$6:$F$155,MATCH(D12,'2. Productos'!$B$6:$B$155,0))*E12,0))+IF(OR(F12="",G12=""),0,IFERROR(INDEX('2. Productos'!$F$6:$F$155,MATCH(F12,'2. Productos'!$B$6:$B$155,0))*G12,0))+IF(OR(H12="",I12=""),0,IFERROR(INDEX('2. Productos'!$F$6:$F$155,MATCH(H12,'2. Productos'!$B$6:$B$155,0))*I12,0))) | N12: =IF(B12="","",N(C12)/60*'1. Costes fijos'!C26) | O12: =IF(B12="","",N(C12)/60*'1. Costes fijos'!C28) | P12: =IF(B12="","",M12+N12+O12+N(J12)) | Q12: =IF(B12="","",IF(N(K12)>=1,"Margen < 100%",P12/(1-N(K12)))) | R12: =IF(OR(B12="",NOT(ISNUMBER(Q12))),"",Q12*(1+N(L12))) | T12: =IF(OR(B12="",NOT(ISNUMBER(S12))),"",S12/(1+N(L12))-P12) | U12: =IF(OR(B12="",NOT(ISNUMBER(S12)),N(S12)=0),"",T12/(S12/(1+N(L12)))) | V12: =IF(U12="","",IF(T12<0,"Pierdes dinero",IF(U12<N(K12),"Por debajo de tu margen","Bien")))
M13: =IF(B13="","",IF(OR(D13="",E13=""),0,IFERROR(INDEX('2. Productos'!$F$6:$F$155,MATCH(D13,'2. Productos'!$B$6:$B$155,0))*E13,0))+IF(OR(F13="",G13=""),0,IFERROR(INDEX('2. Productos'!$F$6:$F$155,MATCH(F13,'2. Productos'!$B$6:$B$155,0))*G13,0))+IF(OR(H13="",I13=""),0,IFERROR(INDEX('2. Productos'!$F$6:$F$155,MATCH(H13,'2. Productos'!$B$6:$B$155,0))*I13,0))) | N13: =IF(B13="","",N(C13)/60*'1. Costes fijos'!C26) | O13: =IF(B13="","",N(C13)/60*'1. Costes fijos'!C28) | P13: =IF(B13="","",M13+N13+O13+N(J13)) | Q13: =IF(B13="","",IF(N(K13)>=1,"Margen < 100%",P13/(1-N(K13)))) | R13: =IF(OR(B13="",NOT(ISNUMBER(Q13))),"",Q13*(1+N(L13))) | T13: =IF(OR(B13="",NOT(ISNUMBER(S13))),"",S13/(1+N(L13))-P13) | U13: =IF(OR(B13="",NOT(ISNUMBER(S13)),N(S13)=0),"",T13/(S13/(1+N(L13)))) | V13: =IF(U13="","",IF(T13<0,"Pierdes dinero",IF(U13<N(K13),"Por debajo de tu margen","Bien")))
M14: =IF(B14="","",IF(OR(D14="",E14=""),0,IFERROR(INDEX('2. Productos'!$F$6:$F$155,MATCH(D14,'2. Productos'!$B$6:$B$155,0))*E14,0))+IF(OR(F14="",G14=""),0,IFERROR(INDEX('2. Productos'!$F$6:$F$155,MATCH(F14,'2. Productos'!$B$6:$B$155,0))*G14,0))+IF(OR(H14="",I14=""),0,IFERROR(INDEX('2. Productos'!$F$6:$F$155,MATCH(H14,'2. Productos'!$B$6:$B$155,0))*I14,0))) | N14: =IF(B14="","",N(C14)/60*'1. Costes fijos'!C26) | O14: =IF(B14="","",N(C14)/60*'1. Costes fijos'!C28) | P14: =IF(B14="","",M14+N14+O14+N(J14)) | Q14: =IF(B14="","",IF(N(K14)>=1,"Margen < 100%",P14/(1-N(K14)))) | R14: =IF(OR(B14="",NOT(ISNUMBER(Q14))),"",Q14*(1+N(L14))) | T14: =IF(OR(B14="",NOT(ISNUMBER(S14))),"",S14/(1+N(L14))-P14) | U14: =IF(OR(B14="",NOT(ISNUMBER(S14)),N(S14)=0),"",T14/(S14/(1+N(L14)))) | V14: =IF(U14="","",IF(T14<0,"Pierdes dinero",IF(U14<N(K14),"Por debajo de tu margen","Bien")))
M15: =IF(B15="","",IF(OR(D15="",E15=""),0,IFERROR(INDEX('2. Productos'!$F$6:$F$155,MATCH(D15,'2. Productos'!$B$6:$B$155,0))*E15,0))+IF(OR(F15="",G15=""),0,IFERROR(INDEX('2. Productos'!$F$6:$F$155,MATCH(F15,'2. Productos'!$B$6:$B$155,0))*G15,0))+IF(OR(H15="",I15=""),0,IFERROR(INDEX('2. Productos'!$F$6:$F$155,MATCH(H15,'2. Productos'!$B$6:$B$155,0))*I15,0))) | N15: =IF(B15="","",N(C15)/60*'1. Costes fijos'!C26) | O15: =IF(B15="","",N(C15)/60*'1. Costes fijos'!C28) | P15: =IF(B15="","",M15+N15+O15+N(J15)) | Q15: =IF(B15="","",IF(N(K15)>=1,"Margen < 100%",P15/(1-N(K15)))) | R15: =IF(OR(B15="",NOT(ISNUMBER(Q15))),"",Q15*(1+N(L15))) | T15: =IF(OR(B15="",NOT(ISNUMBER(S15))),"",S15/(1+N(L15))-P15) | U15: =IF(OR(B15="",NOT(ISNUMBER(S15)),N(S15)=0),"",T15/(S15/(1+N(L15)))) | V15: =IF(U15="","",IF(T15<0,"Pierdes dinero",IF(U15<N(K15),"Por debajo de tu margen","Bien")))
M16: =IF(B16="","",IF(OR(D16="",E16=""),0,IFERROR(INDEX('2. Productos'!$F$6:$F$155,MATCH(D16,'2. Productos'!$B$6:$B$155,0))*E16,0))+IF(OR(F16="",G16=""),0,IFERROR(INDEX('2. Productos'!$F$6:$F$155,MATCH(F16,'2. Productos'!$B$6:$B$155,0))*G16,0))+IF(OR(H16="",I16=""),0,IFERROR(INDEX('2. Productos'!$F$6:$F$155,MATCH(H16,'2. Productos'!$B$6:$B$155,0))*I16,0))) | N16: =IF(B16="","",N(C16)/60*'1. Costes fijos'!C26) | O16: =IF(B16="","",N(C16)/60*'1. Costes fijos'!C28) | P16: =IF(B16="","",M16+N16+O16+N(J16)) | Q16: =IF(B16="","",IF(N(K16)>=1,"Margen < 100%",P16/(1-N(K16)))) | R16: =IF(OR(B16="",NOT(ISNUMBER(Q16))),"",Q16*(1+N(L16))) | T16: =IF(OR(B16="",NOT(ISNUMBER(S16))),"",S16/(1+N(L16))-P16) | U16: =IF(OR(B16="",NOT(ISNUMBER(S16)),N(S16)=0),"",T16/(S16/(1+N(L16)))) | V16: =IF(U16="","",IF(T16<0,"Pierdes dinero",IF(U16<N(K16),"Por debajo de tu margen","Bien")))
M17: =IF(B17="","",IF(OR(D17="",E17=""),0,IFERROR(INDEX('2. Productos'!$F$6:$F$155,MATCH(D17,'2. Productos'!$B$6:$B$155,0))*E17,0))+IF(OR(F17="",G17=""),0,IFERROR(INDEX('2. Productos'!$F$6:$F$155,MATCH(F17,'2. Productos'!$B$6:$B$155,0))*G17,0))+IF(OR(H17="",I17=""),0,IFERROR(INDEX('2. Productos'!$F$6:$F$155,MATCH(H17,'2. Productos'!$B$6:$B$155,0))*I17,0))) | N17: =IF(B17="","",N(C17)/60*'1. Costes fijos'!C26) | O17: =IF(B17="","",N(C17)/60*'1. Costes fijos'!C28) | P17: =IF(B17="","",M17+N17+O17+N(J17)) | Q17: =IF(B17="","",IF(N(K17)>=1,"Margen < 100%",P17/(1-N(K17)))) | R17: =IF(OR(B17="",NOT(ISNUMBER(Q17))),"",Q17*(1+N(L17))) | T17: =IF(OR(B17="",NOT(ISNUMBER(S17))),"",S17/(1+N(L17))-P17) | U17: =IF(OR(B17="",NOT(ISNUMBER(S17)),N(S17)=0),"",T17/(S17/(1+N(L17)))) | V17: =IF(U17="","",IF(T17<0,"Pierdes dinero",IF(U17<N(K17),"Por debajo de tu margen","Bien")))
M18: =IF(B18="","",IF(OR(D18="",E18=""),0,IFERROR(INDEX('2. Productos'!$F$6:$F$155,MATCH(D18,'2. Productos'!$B$6:$B$155,0))*E18,0))+IF(OR(F18="",G18=""),0,IFERROR(INDEX('2. Productos'!$F$6:$F$155,MATCH(F18,'2. Productos'!$B$6:$B$155,0))*G18,0))+IF(OR(H18="",I18=""),0,IFERROR(INDEX('2. Productos'!$F$6:$F$155,MATCH(H18,'2. Productos'!$B$6:$B$155,0))*I18,0))) | N18: =IF(B18="","",N(C18)/60*'1. Costes fijos'!C26) | O18: =IF(B18="","",N(C18)/60*'1. Costes fijos'!C28) | P18: =IF(B18="","",M18+N18+O18+N(J18)) | Q18: =IF(B18="","",IF(N(K18)>=1,"Margen < 100%",P18/(1-N(K18)))) | R18: =IF(OR(B18="",NOT(ISNUMBER(Q18))),"",Q18*(1+N(L18))) | T18: =IF(OR(B18="",NOT(ISNUMBER(S18))),"",S18/(1+N(L18))-P18) | U18: =IF(OR(B18="",NOT(ISNUMBER(S18)),N(S18)=0),"",T18/(S18/(1+N(L18)))) | V18: =IF(U18="","",IF(T18<0,"Pierdes dinero",IF(U18<N(K18),"Por debajo de tu margen","Bien")))
M19: =IF(B19="","",IF(OR(D19="",E19=""),0,IFERROR(INDEX('2. Productos'!$F$6:$F$155,MATCH(D19,'2. Productos'!$B$6:$B$155,0))*E19,0))+IF(OR(F19="",G19=""),0,IFERROR(INDEX('2. Productos'!$F$6:$F$155,MATCH(F19,'2. Productos'!$B$6:$B$155,0))*G19,0))+IF(OR(H19="",I19=""),0,IFERROR(INDEX('2. Productos'!$F$6:$F$155,MATCH(H19,'2. Productos'!$B$6:$B$155,0))*I19,0))) | N19: =IF(B19="","",N(C19)/60*'1. Costes fijos'!C26) | O19: =IF(B19="","",N(C19)/60*'1. Costes fijos'!C28) | P19: =IF(B19="","",M19+N19+O19+N(J19)) | Q19: =IF(B19="","",IF(N(K19)>=1,"Margen < 100%",P19/(1-N(K19)))) | R19: =IF(OR(B19="",NOT(ISNUMBER(Q19))),"",Q19*(1+N(L19))) | T19: =IF(OR(B19="",NOT(ISNUMBER(S19))),"",S19/(1+N(L19))-P19) | U19: =IF(OR(B19="",NOT(ISNUMBER(S19)),N(S19)=0),"",T19/(S19/(1+N(L19)))) | V19: =IF(U19="","",IF(T19<0,"Pierdes dinero",IF(U19<N(K19),"Por debajo de tu margen","Bien")))
M20: =IF(B20="","",IF(OR(D20="",E20=""),0,IFERROR(INDEX('2. Productos'!$F$6:$F$155,MATCH(D20,'2. Productos'!$B$6:$B$155,0))*E20,0))+IF(OR(F20="",G20=""),0,IFERROR(INDEX('2. Productos'!$F$6:$F$155,MATCH(F20,'2. Productos'!$B$6:$B$155,0))*G20,0))+IF(OR(H20="",I20=""),0,IFERROR(INDEX('2. Productos'!$F$6:$F$155,MATCH(H20,'2. Productos'!$B$6:$B$155,0))*I20,0))) | N20: =IF(B20="","",N(C20)/60*'1. Costes fijos'!C26) | O20: =IF(B20="","",N(C20)/60*'1. Costes fijos'!C28) | P20: =IF(B20="","",M20+N20+O20+N(J20)) | Q20: =IF(B20="","",IF(N(K20)>=1,"Margen < 100%",P20/(1-N(K20)))) | R20: =IF(OR(B20="",NOT(ISNUMBER(Q20))),"",Q20*(1+N(L20))) | T20: =IF(OR(B20="",NOT(ISNUMBER(S20))),"",S20/(1+N(L20))-P20) | U20: =IF(OR(B20="",NOT(ISNUMBER(S20)),N(S20)=0),"",T20/(S20/(1+N(L20)))) | V20: =IF(U20="","",IF(T20<0,"Pierdes dinero",IF(U20<N(K20),"Por debajo de tu margen","Bien")))
M21: =IF(B21="","",IF(OR(D21="",E21=""),0,IFERROR(INDEX('2. Productos'!$F$6:$F$155,MATCH(D21,'2. Productos'!$B$6:$B$155,0))*E21,0))+IF(OR(F21="",G21=""),0,IFERROR(INDEX('2. Productos'!$F$6:$F$155,MATCH(F21,'2. Productos'!$B$6:$B$155,0))*G21,0))+IF(OR(H21="",I21=""),0,IFERROR(INDEX('2. Productos'!$F$6:$F$155,MATCH(H21,'2. Productos'!$B$6:$B$155,0))*I21,0))) | N21: =IF(B21="","",N(C21)/60*'1. Costes fijos'!C26) | O21: =IF(B21="","",N(C21)/60*'1. Costes fijos'!C28) | P21: =IF(B21="","",M21+N21+O21+N(J21)) | Q21: =IF(B21="","",IF(N(K21)>=1,"Margen < 100%",P21/(1-N(K21)))) | R21: =IF(OR(B21="",NOT(ISNUMBER(Q21))),"",Q21*(1+N(L21))) | T21: =IF(OR(B21="",NOT(ISNUMBER(S21))),"",S21/(1+N(L21))-P21) | U21: =IF(OR(B21="",NOT(ISNUMBER(S21)),N(S21)=0),"",T21/(S21/(1+N(L21)))) | V21: =IF(U21="","",IF(T21<0,"Pierdes dinero",IF(U21<N(K21),"Por debajo de tu margen","Bien")))
M22: =IF(B22="","",IF(OR(D22="",E22=""),0,IFERROR(INDEX('2. Productos'!$F$6:$F$155,MATCH(D22,'2. Productos'!$B$6:$B$155,0))*E22,0))+IF(OR(F22="",G22=""),0,IFERROR(INDEX('2. Productos'!$F$6:$F$155,MATCH(F22,'2. Productos'!$B$6:$B$155,0))*G22,0))+IF(OR(H22="",I22=""),0,IFERROR(INDEX('2. Productos'!$F$6:$F$155,MATCH(H22,'2. Productos'!$B$6:$B$155,0))*I22,0))) | N22: =IF(B22="","",N(C22)/60*'1. Costes fijos'!C26) | O22: =IF(B22="","",N(C22)/60*'1. Costes fijos'!C28) | P22: =IF(B22="","",M22+N22+O22+N(J22)) | Q22: =IF(B22="","",IF(N(K22)>=1,"Margen < 100%",P22/(1-N(K22)))) | R22: =IF(OR(B22="",NOT(ISNUMBER(Q22))),"",Q22*(1+N(L22))) | T22: =IF(OR(B22="",NOT(ISNUMBER(S22))),"",S22/(1+N(L22))-P22) | U22: =IF(OR(B22="",NOT(ISNUMBER(S22)),N(S22)=0),"",T22/(S22/(1+N(L22)))) | V22: =IF(U22="","",IF(T22<0,"Pierdes dinero",IF(U22<N(K22),"Por debajo de tu margen","Bien")))
M23: =IF(B23="","",IF(OR(D23="",E23=""),0,IFERROR(INDEX('2. Productos'!$F$6:$F$155,MATCH(D23,'2. Productos'!$B$6:$B$155,0))*E23,0))+IF(OR(F23="",G23=""),0,IFERROR(INDEX('2. Productos'!$F$6:$F$155,MATCH(F23,'2. Productos'!$B$6:$B$155,0))*G23,0))+IF(OR(H23="",I23=""),0,IFERROR(INDEX('2. Productos'!$F$6:$F$155,MATCH(H23,'2. Productos'!$B$6:$B$155,0))*I23,0))) | N23: =IF(B23="","",N(C23)/60*'1. Costes fijos'!C26) | O23: =IF(B23="","",N(C23)/60*'1. Costes fijos'!C28) | P23: =IF(B23="","",M23+N23+O23+N(J23)) | Q23: =IF(B23="","",IF(N(K23)>=1,"Margen < 100%",P23/(1-N(K23)))) | R23: =IF(OR(B23="",NOT(ISNUMBER(Q23))),"",Q23*(1+N(L23))) | T23: =IF(OR(B23="",NOT(ISNUMBER(S23))),"",S23/(1+N(L23))-P23) | U23: =IF(OR(B23="",NOT(ISNUMBER(S23)),N(S23)=0),"",T23/(S23/(1+N(L23)))) | V23: =IF(U23="","",IF(T23<0,"Pierdes dinero",IF(U23<N(K23),"Por debajo de tu margen","Bien")))
M24: =IF(B24="","",IF(OR(D24="",E24=""),0,IFERROR(INDEX('2. Productos'!$F$6:$F$155,MATCH(D24,'2. Productos'!$B$6:$B$155,0))*E24,0))+IF(OR(F24="",G24=""),0,IFERROR(INDEX('2. Productos'!$F$6:$F$155,MATCH(F24,'2. Productos'!$B$6:$B$155,0))*G24,0))+IF(OR(H24="",I24=""),0,IFERROR(INDEX('2. Productos'!$F$6:$F$155,MATCH(H24,'2. Productos'!$B$6:$B$155,0))*I24,0))) | N24: =IF(B24="","",N(C24)/60*'1. Costes fijos'!C26) | O24: =IF(B24="","",N(C24)/60*'1. Costes fijos'!C28) | P24: =IF(B24="","",M24+N24+O24+N(J24)) | Q24: =IF(B24="","",IF(N(K24)>=1,"Margen < 100%",P24/(1-N(K24)))) | R24: =IF(OR(B24="",NOT(ISNUMBER(Q24))),"",Q24*(1+N(L24))) | T24: =IF(OR(B24="",NOT(ISNUMBER(S24))),"",S24/(1+N(L24))-P24) | U24: =IF(OR(B24="",NOT(ISNUMBER(S24)),N(S24)=0),"",T24/(S24/(1+N(L24)))) | V24: =IF(U24="","",IF(T24<0,"Pierdes dinero",IF(U24<N(K24),"Por debajo de tu margen","Bien")))
M25: =IF(B25="","",IF(OR(D25="",E25=""),0,IFERROR(INDEX('2. Productos'!$F$6:$F$155,MATCH(D25,'2. Productos'!$B$6:$B$155,0))*E25,0))+IF(OR(F25="",G25=""),0,IFERROR(INDEX('2. Productos'!$F$6:$F$155,MATCH(F25,'2. Productos'!$B$6:$B$155,0))*G25,0))+IF(OR(H25="",I25=""),0,IFERROR(INDEX('2. Productos'!$F$6:$F$155,MATCH(H25,'2. Productos'!$B$6:$B$155,0))*I25,0))) | N25: =IF(B25="","",N(C25)/60*'1. Costes fijos'!C26) | O25: =IF(B25="","",N(C25)/60*'1. Costes fijos'!C28) | P25: =IF(B25="","",M25+N25+O25+N(J25)) | Q25: =IF(B25="","",IF(N(K25)>=1,"Margen < 100%",P25/(1-N(K25)))) | R25: =IF(OR(B25="",NOT(ISNUMBER(Q25))),"",Q25*(1+N(L25))) | T25: =IF(OR(B25="",NOT(ISNUMBER(S25))),"",S25/(1+N(L25))-P25) | U25: =IF(OR(B25="",NOT(ISNUMBER(S25)),N(S25)=0),"",T25/(S25/(1+N(L25)))) | V25: =IF(U25="","",IF(T25<0,"Pierdes dinero",IF(U25<N(K25),"Por debajo de tu margen","Bien")))
M26: =IF(B26="","",IF(OR(D26="",E26=""),0,IFERROR(INDEX('2. Productos'!$F$6:$F$155,MATCH(D26,'2. Productos'!$B$6:$B$155,0))*E26,0))+IF(OR(F26="",G26=""),0,IFERROR(INDEX('2. Productos'!$F$6:$F$155,MATCH(F26,'2. Productos'!$B$6:$B$155,0))*G26,0))+IF(OR(H26="",I26=""),0,IFERROR(INDEX('2. Productos'!$F$6:$F$155,MATCH(H26,'2. Productos'!$B$6:$B$155,0))*I26,0))) | N26: =IF(B26="","",N(C26)/60*'1. Costes fijos'!C26) | O26: =IF(B26="","",N(C26)/60*'1. Costes fijos'!C28) | P26: =IF(B26="","",M26+N26+O26+N(J26)) | Q26: =IF(B26="","",IF(N(K26)>=1,"Margen < 100%",P26/(1-N(K26)))) | R26: =IF(OR(B26="",NOT(ISNUMBER(Q26))),"",Q26*(1+N(L26))) | T26: =IF(OR(B26="",NOT(ISNUMBER(S26))),"",S26/(1+N(L26))-P26) | U26: =IF(OR(B26="",NOT(ISNUMBER(S26)),N(S26)=0),"",T26/(S26/(1+N(L26)))) | V26: =IF(U26="","",IF(T26<0,"Pierdes dinero",IF(U26<N(K26),"Por debajo de tu margen","Bien")))
M27: =IF(B27="","",IF(OR(D27="",E27=""),0,IFERROR(INDEX('2. Productos'!$F$6:$F$155,MATCH(D27,'2. Productos'!$B$6:$B$155,0))*E27,0))+IF(OR(F27="",G27=""),0,IFERROR(INDEX('2. Productos'!$F$6:$F$155,MATCH(F27,'2. Productos'!$B$6:$B$155,0))*G27,0))+IF(OR(H27="",I27=""),0,IFERROR(INDEX('2. Productos'!$F$6:$F$155,MATCH(H27,'2. Productos'!$B$6:$B$155,0))*I27,0))) | N27: =IF(B27="","",N(C27)/60*'1. Costes fijos'!C26) | O27: =IF(B27="","",N(C27)/60*'1. Costes fijos'!C28) | P27: =IF(B27="","",M27+N27+O27+N(J27)) | Q27: =IF(B27="","",IF(N(K27)>=1,"Margen < 100%",P27/(1-N(K27)))) | R27: =IF(OR(B27="",NOT(ISNUMBER(Q27))),"",Q27*(1+N(L27))) | T27: =IF(OR(B27="",NOT(ISNUMBER(S27))),"",S27/(1+N(L27))-P27) | U27: =IF(OR(B27="",NOT(ISNUMBER(S27)),N(S27)=0),"",T27/(S27/(1+N(L27)))) | V27: =IF(U27="","",IF(T27<0,"Pierdes dinero",IF(U27<N(K27),"Por debajo de tu margen","Bien")))
M28: =IF(B28="","",IF(OR(D28="",E28=""),0,IFERROR(INDEX('2. Productos'!$F$6:$F$155,MATCH(D28,'2. Productos'!$B$6:$B$155,0))*E28,0))+IF(OR(F28="",G28=""),0,IFERROR(INDEX('2. Productos'!$F$6:$F$155,MATCH(F28,'2. Productos'!$B$6:$B$155,0))*G28,0))+IF(OR(H28="",I28=""),0,IFERROR(INDEX('2. Productos'!$F$6:$F$155,MATCH(H28,'2. Productos'!$B$6:$B$155,0))*I28,0))) | N28: =IF(B28="","",N(C28)/60*'1. Costes fijos'!C26) | O28: =IF(B28="","",N(C28)/60*'1. Costes fijos'!C28) | P28: =IF(B28="","",M28+N28+O28+N(J28)) | Q28: =IF(B28="","",IF(N(K28)>=1,"Margen < 100%",P28/(1-N(K28)))) | R28: =IF(OR(B28="",NOT(ISNUMBER(Q28))),"",Q28*(1+N(L28))) | T28: =IF(OR(B28="",NOT(ISNUMBER(S28))),"",S28/(1+N(L28))-P28) | U28: =IF(OR(B28="",NOT(ISNUMBER(S28)),N(S28)=0),"",T28/(S28/(1+N(L28)))) | V28: =IF(U28="","",IF(T28<0,"Pierdes dinero",IF(U28<N(K28),"Por debajo de tu margen","Bien")))
M29: =IF(B29="","",IF(OR(D29="",E29=""),0,IFERROR(INDEX('2. Productos'!$F$6:$F$155,MATCH(D29,'2. Productos'!$B$6:$B$155,0))*E29,0))+IF(OR(F29="",G29=""),0,IFERROR(INDEX('2. Productos'!$F$6:$F$155,MATCH(F29,'2. Productos'!$B$6:$B$155,0))*G29,0))+IF(OR(H29="",I29=""),0,IFERROR(INDEX('2. Productos'!$F$6:$F$155,MATCH(H29,'2. Productos'!$B$6:$B$155,0))*I29,0))) | N29: =IF(B29="","",N(C29)/60*'1. Costes fijos'!C26) | O29: =IF(B29="","",N(C29)/60*'1. Costes fijos'!C28) | P29: =IF(B29="","",M29+N29+O29+N(J29)) | Q29: =IF(B29="","",IF(N(K29)>=1,"Margen < 100%",P29/(1-N(K29)))) | R29: =IF(OR(B29="",NOT(ISNUMBER(Q29))),"",Q29*(1+N(L29))) | T29: =IF(OR(B29="",NOT(ISNUMBER(S29))),"",S29/(1+N(L29))-P29) | U29: =IF(OR(B29="",NOT(ISNUMBER(S29)),N(S29)=0),"",T29/(S29/(1+N(L29)))) | V29: =IF(U29="","",IF(T29<0,"Pierdes dinero",IF(U29<N(K29),"Por debajo de tu margen","Bien")))
M30: =IF(B30="","",IF(OR(D30="",E30=""),0,IFERROR(INDEX('2. Productos'!$F$6:$F$155,MATCH(D30,'2. Productos'!$B$6:$B$155,0))*E30,0))+IF(OR(F30="",G30=""),0,IFERROR(INDEX('2. Productos'!$F$6:$F$155,MATCH(F30,'2. Productos'!$B$6:$B$155,0))*G30,0))+IF(OR(H30="",I30=""),0,IFERROR(INDEX('2. Productos'!$F$6:$F$155,MATCH(H30,'2. Productos'!$B$6:$B$155,0))*I30,0))) | N30: =IF(B30="","",N(C30)/60*'1. Costes fijos'!C26) | O30: =IF(B30="","",N(C30)/60*'1. Costes fijos'!C28) | P30: =IF(B30="","",M30+N30+O30+N(J30)) | Q30: =IF(B30="","",IF(N(K30)>=1,"Margen < 100%",P30/(1-N(K30)))) | R30: =IF(OR(B30="",NOT(ISNUMBER(Q30))),"",Q30*(1+N(L30))) | T30: =IF(OR(B30="",NOT(ISNUMBER(S30))),"",S30/(1+N(L30))-P30) | U30: =IF(OR(B30="",NOT(ISNUMBER(S30)),N(S30)=0),"",T30/(S30/(1+N(L30)))) | V30: =IF(U30="","",IF(T30<0,"Pierdes dinero",IF(U30<N(K30),"Por debajo de tu margen","Bien")))
M31: =IF(B31="","",IF(OR(D31="",E31=""),0,IFERROR(INDEX('2. Productos'!$F$6:$F$155,MATCH(D31,'2. Productos'!$B$6:$B$155,0))*E31,0))+IF(OR(F31="",G31=""),0,IFERROR(INDEX('2. Productos'!$F$6:$F$155,MATCH(F31,'2. Productos'!$B$6:$B$155,0))*G31,0))+IF(OR(H31="",I31=""),0,IFERROR(INDEX('2. Productos'!$F$6:$F$155,MATCH(H31,'2. Productos'!$B$6:$B$155,0))*I31,0))) | N31: =IF(B31="","",N(C31)/60*'1. Costes fijos'!C26) | O31: =IF(B31="","",N(C31)/60*'1. Costes fijos'!C28) | P31: =IF(B31="","",M31+N31+O31+N(J31)) | Q31: =IF(B31="","",IF(N(K31)>=1,"Margen < 100%",P31/(1-N(K31)))) | R31: =IF(OR(B31="",NOT(ISNUMBER(Q31))),"",Q31*(1+N(L31))) | T31: =IF(OR(B31="",NOT(ISNUMBER(S31))),"",S31/(1+N(L31))-P31) | U31: =IF(OR(B31="",NOT(ISNUMBER(S31)),N(S31)=0),"",T31/(S31/(1+N(L31)))) | V31: =IF(U31="","",IF(T31<0,"Pierdes dinero",IF(U31<N(K31),"Por debajo de tu margen","Bien")))
M32: =IF(B32="","",IF(OR(D32="",E32=""),0,IFERROR(INDEX('2. Productos'!$F$6:$F$155,MATCH(D32,'2. Productos'!$B$6:$B$155,0))*E32,0))+IF(OR(F32="",G32=""),0,IFERROR(INDEX('2. Productos'!$F$6:$F$155,MATCH(F32,'2. Productos'!$B$6:$B$155,0))*G32,0))+IF(OR(H32="",I32=""),0,IFERROR(INDEX('2. Productos'!$F$6:$F$155,MATCH(H32,'2. Productos'!$B$6:$B$155,0))*I32,0))) | N32: =IF(B32="","",N(C32)/60*'1. Costes fijos'!C26) | O32: =IF(B32="","",N(C32)/60*'1. Costes fijos'!C28) | P32: =IF(B32="","",M32+N32+O32+N(J32)) | Q32: =IF(B32="","",IF(N(K32)>=1,"Margen < 100%",P32/(1-N(K32)))) | R32: =IF(OR(B32="",NOT(ISNUMBER(Q32))),"",Q32*(1+N(L32))) | T32: =IF(OR(B32="",NOT(ISNUMBER(S32))),"",S32/(1+N(L32))-P32) | U32: =IF(OR(B32="",NOT(ISNUMBER(S32)),N(S32)=0),"",T32/(S32/(1+N(L32)))) | V32: =IF(U32="","",IF(T32<0,"Pierdes dinero",IF(U32<N(K32),"Por debajo de tu margen","Bien")))
M33: =IF(B33="","",IF(OR(D33="",E33=""),0,IFERROR(INDEX('2. Productos'!$F$6:$F$155,MATCH(D33,'2. Productos'!$B$6:$B$155,0))*E33,0))+IF(OR(F33="",G33=""),0,IFERROR(INDEX('2. Productos'!$F$6:$F$155,MATCH(F33,'2. Productos'!$B$6:$B$155,0))*G33,0))+IF(OR(H33="",I33=""),0,IFERROR(INDEX('2. Productos'!$F$6:$F$155,MATCH(H33,'2. Productos'!$B$6:$B$155,0))*I33,0))) | N33: =IF(B33="","",N(C33)/60*'1. Costes fijos'!C26) | O33: =IF(B33="","",N(C33)/60*'1. Costes fijos'!C28) | P33: =IF(B33="","",M33+N33+O33+N(J33)) | Q33: =IF(B33="","",IF(N(K33)>=1,"Margen < 100%",P33/(1-N(K33)))) | R33: =IF(OR(B33="",NOT(ISNUMBER(Q33))),"",Q33*(1+N(L33))) | T33: =IF(OR(B33="",NOT(ISNUMBER(S33))),"",S33/(1+N(L33))-P33) | U33: =IF(OR(B33="",NOT(ISNUMBER(S33)),N(S33)=0),"",T33/(S33/(1+N(L33)))) | V33: =IF(U33="","",IF(T33<0,"Pierdes dinero",IF(U33<N(K33),"Por debajo de tu margen","Bien")))
M34: =IF(B34="","",IF(OR(D34="",E34=""),0,IFERROR(INDEX('2. Productos'!$F$6:$F$155,MATCH(D34,'2. Productos'!$B$6:$B$155,0))*E34,0))+IF(OR(F34="",G34=""),0,IFERROR(INDEX('2. Productos'!$F$6:$F$155,MATCH(F34,'2. Productos'!$B$6:$B$155,0))*G34,0))+IF(OR(H34="",I34=""),0,IFERROR(INDEX('2. Productos'!$F$6:$F$155,MATCH(H34,'2. Productos'!$B$6:$B$155,0))*I34,0))) | N34: =IF(B34="","",N(C34)/60*'1. Costes fijos'!C26) | O34: =IF(B34="","",N(C34)/60*'1. Costes fijos'!C28) | P34: =IF(B34="","",M34+N34+O34+N(J34)) | Q34: =IF(B34="","",IF(N(K34)>=1,"Margen < 100%",P34/(1-N(K34)))) | R34: =IF(OR(B34="",NOT(ISNUMBER(Q34))),"",Q34*(1+N(L34))) | T34: =IF(OR(B34="",NOT(ISNUMBER(S34))),"",S34/(1+N(L34))-P34) | U34: =IF(OR(B34="",NOT(ISNUMBER(S34)),N(S34)=0),"",T34/(S34/(1+N(L34)))) | V34: =IF(U34="","",IF(T34<0,"Pierdes dinero",IF(U34<N(K34),"Por debajo de tu margen","Bien")))
M35: =IF(B35="","",IF(OR(D35="",E35=""),0,IFERROR(INDEX('2. Productos'!$F$6:$F$155,MATCH(D35,'2. Productos'!$B$6:$B$155,0))*E35,0))+IF(OR(F35="",G35=""),0,IFERROR(INDEX('2. Productos'!$F$6:$F$155,MATCH(F35,'2. Productos'!$B$6:$B$155,0))*G35,0))+IF(OR(H35="",I35=""),0,IFERROR(INDEX('2. Productos'!$F$6:$F$155,MATCH(H35,'2. Productos'!$B$6:$B$155,0))*I35,0))) | N35: =IF(B35="","",N(C35)/60*'1. Costes fijos'!C26) | O35: =IF(B35="","",N(C35)/60*'1. Costes fijos'!C28) | P35: =IF(B35="","",M35+N35+O35+N(J35)) | Q35: =IF(B35="","",IF(N(K35)>=1,"Margen < 100%",P35/(1-N(K35)))) | R35: =IF(OR(B35="",NOT(ISNUMBER(Q35))),"",Q35*(1+N(L35))) | T35: =IF(OR(B35="",NOT(ISNUMBER(S35))),"",S35/(1+N(L35))-P35) | U35: =IF(OR(B35="",NOT(ISNUMBER(S35)),N(S35)=0),"",T35/(S35/(1+N(L35)))) | V35: =IF(U35="","",IF(T35<0,"Pierdes dinero",IF(U35<N(K35),"Por debajo de tu margen","Bien")))
M36: =IF(B36="","",IF(OR(D36="",E36=""),0,IFERROR(INDEX('2. Productos'!$F$6:$F$155,MATCH(D36,'2. Productos'!$B$6:$B$155,0))*E36,0))+IF(OR(F36="",G36=""),0,IFERROR(INDEX('2. Productos'!$F$6:$F$155,MATCH(F36,'2. Productos'!$B$6:$B$155,0))*G36,0))+IF(OR(H36="",I36=""),0,IFERROR(INDEX('2. Productos'!$F$6:$F$155,MATCH(H36,'2. Productos'!$B$6:$B$155,0))*I36,0))) | N36: =IF(B36="","",N(C36)/60*'1. Costes fijos'!C26) | O36: =IF(B36="","",N(C36)/60*'1. Costes fijos'!C28) | P36: =IF(B36="","",M36+N36+O36+N(J36)) | Q36: =IF(B36="","",IF(N(K36)>=1,"Margen < 100%",P36/(1-N(K36)))) | R36: =IF(OR(B36="",NOT(ISNUMBER(Q36))),"",Q36*(1+N(L36))) | T36: =IF(OR(B36="",NOT(ISNUMBER(S36))),"",S36/(1+N(L36))-P36) | U36: =IF(OR(B36="",NOT(ISNUMBER(S36)),N(S36)=0),"",T36/(S36/(1+N(L36)))) | V36: =IF(U36="","",IF(T36<0,"Pierdes dinero",IF(U36<N(K36),"Por debajo de tu margen","Bien")))
M37: =IF(B37="","",IF(OR(D37="",E37=""),0,IFERROR(INDEX('2. Productos'!$F$6:$F$155,MATCH(D37,'2. Productos'!$B$6:$B$155,0))*E37,0))+IF(OR(F37="",G37=""),0,IFERROR(INDEX('2. Productos'!$F$6:$F$155,MATCH(F37,'2. Productos'!$B$6:$B$155,0))*G37,0))+IF(OR(H37="",I37=""),0,IFERROR(INDEX('2. Productos'!$F$6:$F$155,MATCH(H37,'2. Productos'!$B$6:$B$155,0))*I37,0))) | N37: =IF(B37="","",N(C37)/60*'1. Costes fijos'!C26) | O37: =IF(B37="","",N(C37)/60*'1. Costes fijos'!C28) | P37: =IF(B37="","",M37+N37+O37+N(J37)) | Q37: =IF(B37="","",IF(N(K37)>=1,"Margen < 100%",P37/(1-N(K37)))) | R37: =IF(OR(B37="",NOT(ISNUMBER(Q37))),"",Q37*(1+N(L37))) | T37: =IF(OR(B37="",NOT(ISNUMBER(S37))),"",S37/(1+N(L37))-P37) | U37: =IF(OR(B37="",NOT(ISNUMBER(S37)),N(S37)=0),"",T37/(S37/(1+N(L37)))) | V37: =IF(U37="","",IF(T37<0,"Pierdes dinero",IF(U37<N(K37),"Por debajo de tu margen","Bien")))
M38: =IF(B38="","",IF(OR(D38="",E38=""),0,IFERROR(INDEX('2. Productos'!$F$6:$F$155,MATCH(D38,'2. Productos'!$B$6:$B$155,0))*E38,0))+IF(OR(F38="",G38=""),0,IFERROR(INDEX('2. Productos'!$F$6:$F$155,MATCH(F38,'2. Productos'!$B$6:$B$155,0))*G38,0))+IF(OR(H38="",I38=""),0,IFERROR(INDEX('2. Productos'!$F$6:$F$155,MATCH(H38,'2. Productos'!$B$6:$B$155,0))*I38,0))) | N38: =IF(B38="","",N(C38)/60*'1. Costes fijos'!C26) | O38: =IF(B38="","",N(C38)/60*'1. Costes fijos'!C28) | P38: =IF(B38="","",M38+N38+O38+N(J38)) | Q38: =IF(B38="","",IF(N(K38)>=1,"Margen < 100%",P38/(1-N(K38)))) | R38: =IF(OR(B38="",NOT(ISNUMBER(Q38))),"",Q38*(1+N(L38))) | T38: =IF(OR(B38="",NOT(ISNUMBER(S38))),"",S38/(1+N(L38))-P38) | U38: =IF(OR(B38="",NOT(ISNUMBER(S38)),N(S38)=0),"",T38/(S38/(1+N(L38)))) | V38: =IF(U38="","",IF(T38<0,"Pierdes dinero",IF(U38<N(K38),"Por debajo de tu margen","Bien")))
M39: =IF(B39="","",IF(OR(D39="",E39=""),0,IFERROR(INDEX('2. Productos'!$F$6:$F$155,MATCH(D39,'2. Productos'!$B$6:$B$155,0))*E39,0))+IF(OR(F39="",G39=""),0,IFERROR(INDEX('2. Productos'!$F$6:$F$155,MATCH(F39,'2. Productos'!$B$6:$B$155,0))*G39,0))+IF(OR(H39="",I39=""),0,IFERROR(INDEX('2. Productos'!$F$6:$F$155,MATCH(H39,'2. Productos'!$B$6:$B$155,0))*I39,0))) | N39: =IF(B39="","",N(C39)/60*'1. Costes fijos'!C26) | O39: =IF(B39="","",N(C39)/60*'1. Costes fijos'!C28) | P39: =IF(B39="","",M39+N39+O39+N(J39)) | Q39: =IF(B39="","",IF(N(K39)>=1,"Margen < 100%",P39/(1-N(K39)))) | R39: =IF(OR(B39="",NOT(ISNUMBER(Q39))),"",Q39*(1+N(L39))) | T39: =IF(OR(B39="",NOT(ISNUMBER(S39))),"",S39/(1+N(L39))-P39) | U39: =IF(OR(B39="",NOT(ISNUMBER(S39)),N(S39)=0),"",T39/(S39/(1+N(L39)))) | V39: =IF(U39="","",IF(T39<0,"Pierdes dinero",IF(U39<N(K39),"Por debajo de tu margen","Bien")))
M40: =IF(B40="","",IF(OR(D40="",E40=""),0,IFERROR(INDEX('2. Productos'!$F$6:$F$155,MATCH(D40,'2. Productos'!$B$6:$B$155,0))*E40,0))+IF(OR(F40="",G40=""),0,IFERROR(INDEX('2. Productos'!$F$6:$F$155,MATCH(F40,'2. Productos'!$B$6:$B$155,0))*G40,0))+IF(OR(H40="",I40=""),0,IFERROR(INDEX('2. Productos'!$F$6:$F$155,MATCH(H40,'2. Productos'!$B$6:$B$155,0))*I40,0))) | N40: =IF(B40="","",N(C40)/60*'1. Costes fijos'!C26) | O40: =IF(B40="","",N(C40)/60*'1. Costes fijos'!C28) | P40: =IF(B40="","",M40+N40+O40+N(J40)) | Q40: =IF(B40="","",IF(N(K40)>=1,"Margen < 100%",P40/(1-N(K40)))) | R40: =IF(OR(B40="",NOT(ISNUMBER(Q40))),"",Q40*(1+N(L40))) | T40: =IF(OR(B40="",NOT(ISNUMBER(S40))),"",S40/(1+N(L40))-P40) | U40: =IF(OR(B40="",NOT(ISNUMBER(S40)),N(S40)=0),"",T40/(S40/(1+N(L40)))) | V40: =IF(U40="","",IF(T40<0,"Pierdes dinero",IF(U40<N(K40),"Por debajo de tu margen","Bien")))
M41: =IF(B41="","",IF(OR(D41="",E41=""),0,IFERROR(INDEX('2. Productos'!$F$6:$F$155,MATCH(D41,'2. Productos'!$B$6:$B$155,0))*E41,0))+IF(OR(F41="",G41=""),0,IFERROR(INDEX('2. Productos'!$F$6:$F$155,MATCH(F41,'2. Productos'!$B$6:$B$155,0))*G41,0))+IF(OR(H41="",I41=""),0,IFERROR(INDEX('2. Productos'!$F$6:$F$155,MATCH(H41,'2. Productos'!$B$6:$B$155,0))*I41,0))) | N41: =IF(B41="","",N(C41)/60*'1. Costes fijos'!C26) | O41: =IF(B41="","",N(C41)/60*'1. Costes fijos'!C28) | P41: =IF(B41="","",M41+N41+O41+N(J41)) | Q41: =IF(B41="","",IF(N(K41)>=1,"Margen < 100%",P41/(1-N(K41)))) | R41: =IF(OR(B41="",NOT(ISNUMBER(Q41))),"",Q41*(1+N(L41))) | T41: =IF(OR(B41="",NOT(ISNUMBER(S41))),"",S41/(1+N(L41))-P41) | U41: =IF(OR(B41="",NOT(ISNUMBER(S41)),N(S41)=0),"",T41/(S41/(1+N(L41)))) | V41: =IF(U41="","",IF(T41<0,"Pierdes dinero",IF(U41<N(K41),"Por debajo de tu margen","Bien")))
M42: =IF(B42="","",IF(OR(D42="",E42=""),0,IFERROR(INDEX('2. Productos'!$F$6:$F$155,MATCH(D42,'2. Productos'!$B$6:$B$155,0))*E42,0))+IF(OR(F42="",G42=""),0,IFERROR(INDEX('2. Productos'!$F$6:$F$155,MATCH(F42,'2. Productos'!$B$6:$B$155,0))*G42,0))+IF(OR(H42="",I42=""),0,IFERROR(INDEX('2. Productos'!$F$6:$F$155,MATCH(H42,'2. Productos'!$B$6:$B$155,0))*I42,0))) | N42: =IF(B42="","",N(C42)/60*'1. Costes fijos'!C26) | O42: =IF(B42="","",N(C42)/60*'1. Costes fijos'!C28) | P42: =IF(B42="","",M42+N42+O42+N(J42)) | Q42: =IF(B42="","",IF(N(K42)>=1,"Margen < 100%",P42/(1-N(K42)))) | R42: =IF(OR(B42="",NOT(ISNUMBER(Q42))),"",Q42*(1+N(L42))) | T42: =IF(OR(B42="",NOT(ISNUMBER(S42))),"",S42/(1+N(L42))-P42) | U42: =IF(OR(B42="",NOT(ISNUMBER(S42)),N(S42)=0),"",T42/(S42/(1+N(L42)))) | V42: =IF(U42="","",IF(T42<0,"Pierdes dinero",IF(U42<N(K42),"Por debajo de tu margen","Bien")))
...
